<?xml version="1.0" ?>
<robot name="rover_crane_nbv">

    <material name="black">
        <color rgba="0 0 0 1"/>
    </material>
    <material name="gold">
        <color rgba="1 0.882 0 1"/>
    </material>
    <material name="lunar_surface">
        <color rgba="0.85 0.85 0.85 1"/>
    </material>

<!-- Start Rover -->
    <!-- Base -->
    <link name="rover_base_link">
        <visual>
            <origin xyz="0 0 0.005" rpy="0 0 0" />
            <geometry>
               <box size="6 6 0.01"/>
            </geometry>
            <material name="lunar_surface"/>
        </visual>
        <collision>
            <origin xyz="0 0 0.005" rpy="0 0 0" />
            <geometry>
                <box size="6 6 0.01"/>
            </geometry>
        </collision>   
        
        <visual>
            <origin xyz="0 0 0.25" rpy="0 0 0" />
            <geometry>
               <box size="2.6 1.5 0.5"/>
            </geometry>
            <material name="gold"/>
        </visual>
        <collision>
            <origin xyz="0 0 0.25" rpy="0 0 0" />
            <geometry>
                <box size="2.6 1.5 0.5"/>
            </geometry>
        </collision>   
    </link>
    
    <link name="crane_yaw">
        <visual>
            <origin xyz="0 0 0.05" rpy="0 0 0" />
            <geometry>
               <cylinder length="0.1" radius="0.2"/>
            </geometry>
            <material name="gold"/>
        </visual>
        <collision>
            <origin xyz="0 0 0.05" rpy="0 0 0" />
            <geometry>
                <cylinder length="0.1" radius="0.2"/>
            </geometry>
        </collision>    
    </link>
    
    <joint name="joint0_1" type="revolute">
        <parent link="rover_base_link"/>
        <child link="crane_yaw"/>
        <origin xyz="1.1 0 0.5" rpy="0 0 0"/>
        <axis xyz="0 0 1"/>
        <limit lower="-0.523599" upper="0.523599" effort="0" velocity="0"/>
    </joint>

    <link name="crane_link1">
        <visual>
            <origin xyz="0 0 0" rpy="1.5708 0 0" />
            <geometry>
               <cylinder length="0.4" radius="0.2"/>
            </geometry>
            <material name="gold"/>
        </visual>
        <collision>
            <origin xyz="0 0 0" rpy="1.5708 0 0" />
            <geometry>
                <cylinder length="0.4" radius="0.2"/>
            </geometry>
        </collision>  

        <visual>
            <origin xyz="-1.698 0 0" rpy="0 0 0" />
            <geometry>
               <box size="3.396 0.4 0.4"/>
            </geometry>
            <material name="gold"/>
        </visual>
        <collision>
            <origin xyz="-1.698 0 0" rpy="0 0 0" />
            <geometry>
                <box size="3.396 0.4 0.4"/>
            </geometry>
        </collision>
    </link>


    <joint name="joint0_2" type="revolute">
        <parent link="crane_yaw"/> 
        <child link="crane_link1"/>
        <origin xyz="0 0 0.3" rpy="0 1.5708 0"/>
        <axis xyz="0 1 0"/>
        <limit lower="0.0" upper="1.5708" effort="0" velocity="0"/>
    </joint>


    <link name="crane_link2">
        <visual>
            <origin xyz="1.132 0 0" rpy="0 0 0" />
            <geometry>
               <box size="2.264 0.2 0.2"/>
            </geometry>
            <material name="gold"/>
        </visual>
        <collision>
            <origin xyz="1.132 0 0" rpy="0 0 0" />
            <geometry>
                <box size="2.264 0.2 0.2"/>
            </geometry>
        </collision>
    </link>

    <joint name="joint0_3" type="prismatic">
        <parent link="crane_link1"/>
        <child link="crane_link2"/>
        <origin xyz="-3.396 0 0" rpy="0 0 0"/>
        <axis xyz="-1 0 0"/>
        <limit lower="0.0" upper="2.264" effort="0" velocity="0"/>
    </joint>
    
    <link name="tip">
        <visual>
            <!-- z = (-0.17 - 0.1) -->
            <origin xyz="-0.1 0 -0.17" rpy="0 1.5708 0" />
            <geometry>
               <box size="0.34 0.2 0.2"/>
            </geometry>
            <material name="gold"/>
        </visual>
        <collision>
            <origin xyz="-0.1 0 -0.17" rpy="0 1.5708 0" />
            <geometry>
                <box size="0.34 0.2 0.2"/>
            </geometry>
        </collision>   
    </link>

    <joint name="tip_joint" type="fixed">
        <parent link="crane_link2"/>
        <child link="tip"/>
        <origin xyz="0 0 -0.1" rpy="0 -1.26165662836 0"/>
    </joint>

<!-- START NBV -->
  <link name="base_link">
    <visual>
      <origin xyz="0 0 0" rpy="0 0 0" />
      <geometry>
        <mesh filename="package://../nbv/urdf/stl/mount.stl" />
      </geometry>
    </visual>
    <collision>
      <origin xyz="0 0 0" rpy="0 0 0" />
      <geometry>
        <mesh filename="package://../nbv/urdf/stl/mount.stl" />
      </geometry>
    </collision>

    <!-- 
    <inertial>
      <mass value="0.1" />
      <inertia ixx="0.03" iyy="0.03" izz="0.03" ixy="0.0" ixz="0.0" iyz="0.0" />
    </inertial>
    -->
  </link>

<!-- CHANGE WHERE NBV IS PLACED HERE -->
<!-- NBV ATTACHED TO ARM TIP
    <joint name="nbv_rover_fix" type="fixed">
        <parent link="tip"/>
        <child link="base_link"/>
        <origin xyz="0 0 0" rpy="0 0 0"/>
    </joint>
-->
<!-- <box size="2.4 1.5 0.5"/> -->
<!-- NBV ATTACHED TO ROVER DECK
    <joint name="nbv_rover_fix" type="fixed">
        <parent link="rover_base_link"/>
        <child link="base_link"/>
        <origin xyz="0 0 0.5" rpy="0 0 0"/>
    </joint>
-->
<!-- NBV ATTACHED TO ROVER FRONT BUMPER -->

    <joint name="nbv_rover_fix" type="fixed">
        <parent link="rover_base_link"/>
        <child link="base_link"/>
        <origin xyz="-1.0 0.5 0.5" rpy="0 0 0"/>
    </joint>

  
  <!-- Base-Seg1 -->
  <link name="base-seg1">
    <visual>
      <origin xyz="0 0 -0.2491" rpy="0 0 -1.57079632679" />
      <geometry>
        <mesh filename="package://../nbv/urdf/stl/mount-seg1.stl" />
      </geometry>
    </visual>
    <collision>
      <origin xyz="0 0 -0.2491" rpy="0 0 -1.57079632679" />
      <geometry>
        <mesh filename="package://../nbv/urdf/stl/mount-seg1.stl" />
      </geometry>
    </collision>
    <inertial>
      <mass value="0.1" />
      <inertia ixx="0.03" iyy="0.03" izz="0.03" ixy="0.0" ixz="0.0" iyz="0.0" />
    </inertial>
  </link>
  <joint name="joint1" type="revolute">
    <parent link="base_link" />
    <child link="base-seg1" />
    <origin xyz="0 0 0.2872" rpy="0 0 0" />
    <axis xyz="0 0 1" />
    <limit effort="300" velocity="0.25" lower="-3.14159" upper="3.14159" />
  </joint>
  
  
  <!-- Seg1 -->
  <link name="seg1">
    <visual>
      <origin xyz="0 0 0" rpy="0 1.57079632679 -1.57079632679" />
      <geometry>
        <mesh filename="package://../nbv/urdf/stl/seg1.stl" />
      </geometry>
    </visual>
    <collision>
      <origin xyz="0 0 0" rpy="0 1.57079632679 -1.57079632679" />
      <geometry>
        <mesh filename="package://../nbv/urdf/stl/seg1.stl" />
      </geometry>
    </collision>

    <inertial>
      <mass value="0.1" />
      <inertia ixx="0.03" iyy="0.03" izz="0.03" ixy="0.0" ixz="0.0" iyz="0.0" />
    </inertial>

  </link>
  <joint name="joint2" type="revolute">
    <parent link="base-seg1" />
    <child link="seg1" />
    <origin xyz="0 0 0" rpy="1.57079632679 0 0" />
    <axis xyz="0 0 1" />
    <limit effort="300" velocity="0.25" lower="-0.785" upper="3.925" />
  </joint>
  <!-- Seg1-Seg2 -->
  <link name="seg1-seg2">
    <visual>
      <origin xyz="0 0 0" rpy="0 1.57079632679 0" />
      <geometry>
        <mesh filename="package://../nbv/urdf/stl/seg1-seg2.stl" />
      </geometry>
    </visual>
    <collision>
      <origin xyz="0 0 0" rpy="0 1.57079632679 0" />
      <geometry>
        <mesh filename="package://../nbv/urdf/stl/seg1-seg2.stl" />
      </geometry>
    </collision>

    <inertial>
      <mass value="0.1" />
      <inertia ixx="0.03" iyy="0.03" izz="0.03" ixy="0.0" ixz="0.0" iyz="0.0" />
    </inertial>

  </link>
  <joint name="joint3" type="revolute">
    <parent link="seg1" />
    <child link="seg1-seg2" />
    <origin xyz="0.5589 0 0" rpy="3.14159265359 0 0" />
    <axis xyz="0 0 1" />
    <limit effort="300" velocity="0.25" lower="-1.5707" upper="1.5707" />
  </joint>
  <!-- Seg2 -->
  <link name="seg2">
    <visual>
      <origin xyz="0 0 -0.4368" rpy="0 0 1.57079632679" />
      <geometry>
        <mesh filename="package://../nbv/urdf/stl/seg2.stl" />
      </geometry>
    </visual>
    <collision>
      <origin xyz="0 0 -0.4368" rpy="0 0 1.57079632679" />
      <geometry>
        <mesh filename="package://../nbv/urdf/stl/seg2.stl" />
      </geometry>
    </collision>

    <inertial>
      <mass value="0.1" />
      <inertia ixx="0.03" iyy="0.03" izz="0.03" ixy="0.0" ixz="0.0" iyz="0.0" />
    </inertial>

  </link>
  <joint name="joint4" type="continuous">
    <parent link="seg1-seg2" />
    <child link="seg2" />
    <origin xyz="0.15140 -0.5388 0" rpy="1.57079632679 0 0" />
    <axis xyz="0 0 1" />
    <limit effort="300" velocity="0.25" lower="-3.14159" upper="3.14159" />
  </joint>
  <!-- End -->
  <link name="end">
    <visual>
      <origin xyz="0 0 0" rpy="0 1.57079632679 -1.57079632679" />
      <geometry>
        <mesh filename="package://../nbv/urdf/stl/end.stl" />
      </geometry>
    </visual>
    <collision>
      <origin xyz="0 0 0" rpy="0 1.57079632679 -1.57079632679" />
      <geometry>
        <mesh filename="package://../nbv/urdf/stl/end.stl" />
      </geometry>
    </collision>

    <inertial>
      <mass value="0.1" />
      <inertia ixx="0.03" iyy="0.03" izz="0.03" ixy="0.0" ixz="0.0" iyz="0.0" />
    </inertial>

  </link>
  <joint name="joint5" type="revolute">
    <parent link="seg2" />
    <child link="end" />
    <origin xyz="0 0 0" rpy="-1.57079632679 0 0" />
    <axis xyz="0 0 1" />
    <limit effort="300" velocity="0.25" lower="-1.78" upper="1.78" />
  </joint>
  <!-- Manipulator -->
  <!-- Another joint for the rotation of whatever is attached to the end of NBV.
    As there is no model for this, it's currently just a big cube when uncommented. -->
  <link name="manip">
    <visual>
      <origin xyz="0 0 0.3" rpy="0 0 0" />
      <geometry>
        <box size="0.1 0.1 0.1" />
      </geometry>
    </visual>
    <collision>
      <origin xyz="0 0 0.3" rpy="0 0 0" />
      <geometry>
        <box size="0.1 0.1 0.1" />
      </geometry>
    </collision>

    <inertial>
      <mass value="0.1" />
      <inertia ixx="0.03" iyy="0.03" izz="0.03" ixy="0.0" ixz="0.0" iyz="0.0" />
    </inertial>

  </link>
  <joint name="joint6" type="continuous">
    <parent link="end" />
    <child link="manip" />
    <origin xyz="0 0 0" rpy="1.57079632679 0 0" />
    <axis xyz="0 0 1" />
    <limit effort="300" velocity="0.25" lower="-6.28" upper="6.28" />
  </joint>

</robot>