<?xml version="1.0" ?>
<robot name="rover_crane">

    <material name="gold">
        <color rgba="1 0.882 0 1"/>
    </material>

    <link name="rover_base_link">        
        <visual>
            <origin xyz="0 0 0.125" rpy="0 0 0" />
            <geometry>
               <box size="2.6 1.5 0.2"/>
            </geometry>
            <material name="gold"/>
        </visual>
        <collision>
            <origin xyz="0 0 0.125" rpy="0 0 0" />
            <geometry>
                <box size="2.6 1.5 0.2"/>
            </geometry>
        </collision>

        <visual>
            <!-- 1.3 - 0.32 -->
            <origin xyz=".98 0 0.35" rpy="0 0 0" />
            <geometry>
               <box size="0.64 1.5 0.3"/>
            </geometry>
            <material name="gold"/>
        </visual>
        <collision>
            <origin xyz=".98 0 0.35" rpy="0 0 0" />
            <geometry>
                <box size="0.64 1.5 0.3"/>
            </geometry>
        </collision>  
    </link>
    
    <link name="crane_base_link"/>

    <joint name="fix_to_chassis" type="fixed">
        <parent link="rover_base_link"/>
        <child link="crane_base_link"/>
        <origin xyz="1.1 0 0.5" rpy="0 0 0"/>
    </joint>

    <link name="crane_yaw">
        <visual>
            <origin xyz="0 0 0.05" rpy="0 0 0" />
            <geometry>
               <cylinder length="0.1" radius="0.2"/>
            </geometry>
            <material name="gold"/>
        </visual>
        <collision>
            <origin xyz="0 0 0.05" rpy="0 0 0" />
            <geometry>
                <cylinder length="0.1" radius="0.2"/>
            </geometry>
        </collision>    
    </link>
    
    <joint name="joint0_1" type="revolute">
        <parent link="crane_base_link"/>
        <child link="crane_yaw"/>
        <origin xyz="0 0 0" rpy="0 0 0"/>
        <axis xyz="0 0 1"/>
        <limit lower="-0.523599" upper="0.523599" effort="0" velocity="0"/>
    </joint>

    <link name="crane_link1">
        <visual>
            <origin xyz="0 0 0" rpy="1.5708 0 0" />
            <geometry>
               <cylinder length="0.4" radius="0.2"/>
            </geometry>
            <material name="gold"/>
        </visual>
        <collision>
            <origin xyz="0 0 0" rpy="1.5708 0 0" />
            <geometry>
                <cylinder length="0.4" radius="0.2"/>
            </geometry>
        </collision>  

        <visual>
            <origin xyz="-0.7 0 0" rpy="0 0 0" />
            <geometry>
               <box size="1.4 0.4 0.4"/>
            </geometry>
            <material name="gold"/>
        </visual>
        <collision>
            <origin xyz="-0.7 0 0" rpy="0 0 0" />
            <geometry>
                <box size="1.4 0.4 0.4"/>
            </geometry>
        </collision>
    </link>


    <joint name="joint0_2" type="revolute">
        <parent link="crane_yaw"/> 
        <child link="crane_link1"/>
        <origin xyz="0 0 0.3" rpy="0 1.5708 0"/>
        <axis xyz="0 1 0"/>
        <limit lower="0.0" upper="1.5708" effort="0" velocity="0"/>
    </joint>


    <link name="crane_link2">
        <visual>
            <origin xyz="0.55 0 0" rpy="0 0 0" />
            <geometry>
               <box size="1.1 0.35 0.35"/>
            </geometry>
            <material name="gold"/>
        </visual>
        <collision>
            <origin xyz="0.55 0 0" rpy="0 0 0" />
            <geometry>
                <box size="1.1 0.35 0.35"/>
            </geometry>
        </collision>
    </link>

    <joint name="joint0_3" type="prismatic">
        <parent link="crane_link1"/>
        <child link="crane_link2"/>
        <origin xyz="-1.4 0 0" rpy="0 0 0"/>
        <axis xyz="-1 0 0"/>
        <limit lower="0.0" upper="1.1" effort="0" velocity="0"/>
    </joint>

    <link name="crane_link3">
        <visual>
            <origin xyz="0.55 0 0" rpy="0 0 0" />
            <geometry>
               <box size="1.1 0.3 0.3"/>
            </geometry>
            <material name="gold"/>
        </visual>
        <collision>
            <origin xyz="0.55 0 0" rpy="0 0 0" />
            <geometry>
                <box size="1.1 0.3 0.3"/>
            </geometry>
        </collision>
    </link>

    <joint name="joint0_4" type="prismatic">
        <parent link="crane_link2"/>
        <child link="crane_link3"/>
        <origin xyz="0 0 0" rpy="0 0 0"/>
        <axis xyz="-1 0 0"/>
        <limit lower="0.0" upper="1.1" effort="0" velocity="0"/>
    </joint>

    <link name="crane_link4">
        <visual>
            <origin xyz="0.55 0 0" rpy="0 0 0" />
            <geometry>
               <box size="1.1 0.25 0.25"/>
            </geometry>
            <material name="gold"/>
        </visual>
        <collision>
            <origin xyz="0.55 0 0" rpy="0 0 0" />
            <geometry>
                <box size="1.1 0.25 0.25"/>
            </geometry>
        </collision>
    </link>

    <joint name="joint0_5" type="prismatic">
        <parent link="crane_link3"/>
        <child link="crane_link4"/>
        <origin xyz="0 0 0" rpy="0 0 0"/>
        <axis xyz="-1 0 0"/>
        <limit lower="0.0" upper="1.1" effort="0" velocity="0"/>
    </joint>

    <link name="tip">
        <visual>
            <origin xyz="0 0 0" rpy="1.5708 0 0" />
            <geometry>
               <cylinder length="0.2" radius="0.2"/>
            </geometry>
            <material name="gold"/>
        </visual>
        <collision>
            <origin xyz="0 0 0" rpy="1.5708 0 0" />
            <geometry>
               <cylinder length="0.2" radius="0.2"/>
            </geometry>
            <material name="gold"/>
        </collision>
        
        <visual>
            <!-- 0.5 + 0.054 -->
            <origin xyz="0 0 -0.554" rpy="0 0 0" />
            <geometry>
               <box size="0.2 0.2 1.0"/>
            </geometry>
            <material name="gold"/>
        </visual>
        <collision>
            <origin xyz="0 0 -0.554" rpy="0 0 0" />
            <geometry>
               <box size="0.2 0.2 1.0"/>
            </geometry>
            <material name="gold"/>
        </collision>
    </link>

    <joint name="tip_joint" type="revolute">
        <parent link="crane_link4"/>
        <child link="tip"/>
        <origin xyz="0 0 0" rpy="0 0 0"/>
        <axis xyz="0 1 0"/>
        <limit lower="0.0" upper="1.1" effort="0" velocity="0"/>
    </joint>

    <link name="tip_to_tippy"/>

    <joint name="tippy_tip" type="fixed">
        <parent link="tip"/>
        <child link="tip_to_tippy"/>
        <origin xyz="0 0 0" rpy="0 0 0"/>
    </joint>
    
    
    <link name="dyma_base_link">
    </link>

    <joint name="tippy_to_base" type="fixed">
        <parent link="tip_to_tippy"/>
        <child link="dyma_base_link"/>
        <origin xyz="0 -0.1 -1.0" rpy="1.5708 0 0"/>
    </joint>

    <link name="shld_yaw">
        <visual>
            <origin xyz="0 0 0" rpy="0 0 0" />
            <geometry>
               <mesh filename="package://dymaflight/urdf/meshes/shld_yaw.stl" scale="0.001 0.001 0.001"/>
            </geometry>
        </visual>
        <collision>
            <origin xyz="0 0 0" rpy="0 0 0" />
            <geometry>
               <mesh filename="package://dymaflight/urdf/meshes/shld_yaw.stl" scale="0.001 0.001 0.001"/>
            </geometry>
        </collision>
    </link>

    <joint name="joint1" type="revolute">
        <parent link="dyma_base_link" />
        <child link="shld_yaw" />
        <origin xyz="0 0 0.18161" rpy="0 0 0" />
        <axis xyz="0 0 1" />
        <limit effort="300" velocity="0.25" lower="-3.14159" upper="3.14159" />
    </joint>

    <link name="shld_ptch">
        <visual>
            <origin xyz="0 0 0" rpy="0 0 0" />
            <geometry>
               <mesh filename="package://dymaflight/urdf/meshes/shld_ptch.stl" scale="0.001 0.001 0.001"/>
            </geometry>
        </visual>
        <collision>
            <origin xyz="0 0 0" rpy="0 0 0" />
            <geometry>
               <mesh filename="package://dymaflight/urdf/meshes/shld_ptch.stl" scale="0.001 0.001 0.001"/>
            </geometry>
        </collision>
    </link>

    <joint name="joint2" type="revolute">
        <parent link="shld_yaw" />
        <child link="shld_ptch" />

        <origin xyz="0 0 0" rpy="-1.5708 0 3.14159 " />
        <axis xyz="0 0 1" />
        <limit effort="300" velocity="0.25" lower="-3.14159" upper="3.14159" />
    </joint>

    <link name="shld_roll">
        <visual>
            <origin xyz="0 0 0" rpy="0 0 0" />
            <geometry>
               <mesh filename="package://dymaflight/urdf/meshes/shld_roll.stl" scale="0.001 0.001 0.001"/>
            </geometry>
        </visual>
        <collision>
            <origin xyz="0 0 0" rpy="0 0 0" />
            <geometry>
               <mesh filename="package://dymaflight/urdf/meshes/shld_roll.stl" scale="0.001 0.001 0.001"/>
            </geometry>
        </collision>
    </link>

    <joint name="joint3" type="revolute">
        <parent link="shld_ptch" />
        <child link="shld_roll" />
        <origin xyz="0 -0.430022 0" rpy="1.5708 0 0" />
        <axis xyz="0 0 1" />
        <limit effort="300" velocity="0.25" lower="-3.14159" upper="3.14159" />
    </joint>

    <link name="elbw_ptch">
        <visual>
            <origin xyz="0 0 0" rpy="0 0 0" />
            <geometry>
               <mesh filename="package://dymaflight/urdf/meshes/elbw_ptch.stl" scale="0.001 0.001 0.001"/>
            </geometry>
        </visual>
        <collision>
            <origin xyz="0 0 0" rpy="0 0 0" />
            <geometry>
               <mesh filename="package://dymaflight/urdf/meshes/elbw_ptch.stl" scale="0.001 0.001 0.001"/>
            </geometry>
        </collision>
    </link>

    <joint name="joint4" type="revolute">
        <parent link="shld_roll" />
        <child link="elbw_ptch" />
        <origin xyz="0.041402 0 0" rpy="-1.5708 -3.14159 0" />
        <axis xyz="0 0 1" />
        <limit effort="300" velocity="0.25" lower="-3.14159" upper="3.14159" />
    </joint>

    <link name="wrst_roll">
        <visual>
            <origin xyz="0 0 0" rpy="0 0 0" />
            <geometry>
               <mesh filename="package://dymaflight/urdf/meshes/wrst_roll.stl" scale="0.001 0.001 0.001"/>
            </geometry>
        </visual>
        <collision>
            <origin xyz="0 0 0" rpy="0 0 0" />
            <geometry>
               <mesh filename="package://dymaflight/urdf/meshes/wrst_roll.stl" scale="0.001 0.001 0.001"/>
            </geometry>
        </collision>
    </link>

    <joint name="joint5" type="revolute">
        <parent link="elbw_ptch" />
        <child link="wrst_roll" />
        <origin xyz="0.041402 0.37084 0" rpy="-1.5708 0 0" />
        <axis xyz="0 0 1" />
        <limit effort="300" velocity="0.25" lower="-3.14159" upper="3.14159" />
    </joint>

    <link name="wrst_ptch">
        <visual>
            <origin xyz="0 0 0" rpy="0 0 0" />
            <geometry>
               <mesh filename="package://dymaflight/urdf/meshes/wrst_ptch.stl" scale="0.001 0.001 0.001"/>
            </geometry>
        </visual>
        <collision>
            <origin xyz="0 0 0" rpy="0 0 0" />
            <geometry>
               <mesh filename="package://dymaflight/urdf/meshes/wrst_ptch.stl" scale="0.001 0.001 0.001"/>
            </geometry>
        </collision>
    </link>

    <joint name="joint6" type="revolute">
        <parent link="wrst_roll" />
        <child link="wrst_ptch" />
        <origin xyz="0.033274 -0.007366 0" rpy="-1.5708 0 3.14159" />
        <axis xyz="0 0 1" />
        <limit effort="300" velocity="0.25" lower="-3.14159" upper="3.14159" />
    </joint>

    <link name="tool_roll">
        <visual>
            <origin xyz="0 0 0" rpy="0 0 0" />
            <geometry>
               <mesh filename="package://dymaflight/urdf/meshes/tool_roll.stl" scale="0.001 0.001 0.001"/>
            </geometry>
        </visual>
        <collision>
            <origin xyz="0 0 0" rpy="0 0 0" />
            <geometry>
               <mesh filename="package://dymaflight/urdf/meshes/tool_roll.stl" scale="0.001 0.001 0.001"/>
            </geometry>
        </collision>
    </link>

    <joint name="joint7" type="revolute">
        <parent link="wrst_ptch" />
        <child link="tool_roll" />
        <origin xyz="0.033274 0 0" rpy="1.5708 0 0" />
        <axis xyz="0 0 1" />
        <limit effort="300" velocity="0.25" lower="-3.14159" upper="3.14159" />
    </joint>

</robot>