<?xml version="1.0" ?>
<robot name="rover_crane">

    <material name="black">
        <color rgba="0 0 0 1"/>
    </material>
    <material name="gold">
        <color rgba="1 0.882 0 1"/>
    </material>
    <material name="lunar_surface">
        <color rgba="0.85 0.85 0.85 1"/>
    </material>

    <link name="ground"/>
    <!-- Base -->
    <link name="rover_base_link"> 
        <visual>
            <origin xyz="0 0 0.25" rpy="0 0 0" />
            <geometry>
               <box size="2.6 1.5 0.5"/>
            </geometry>
            <material name="gold"/>
        </visual>
        <collision>
            <origin xyz="0 0 0.25" rpy="0 0 0" />
            <geometry>
                <box size="2.6 1.5 0.5"/>
            </geometry>
        </collision>   
    </link>

    <joint name="world_rotate" type="fixed">
        <parent link="ground"/>
        <child link="rover_base_link"/>
        <origin xyz="0 0 0" rpy="-1.5708 0 0"/>
    </joint>
    
    <link name="crane_yaw">
        <visual>
            <origin xyz="0 0 0.05" rpy="0 0 0" />
            <geometry>
               <cylinder length="0.1" radius="0.2"/>
            </geometry>
            <material name="gold"/>
        </visual>
        <collision>
            <origin xyz="0 0 0.05" rpy="0 0 0" />
            <geometry>
                <cylinder length="0.1" radius="0.2"/>
            </geometry>
        </collision>    
    </link>
    
    <joint name="joint0_1" type="revolute">
        <parent link="rover_base_link"/>
        <child link="crane_yaw"/>
        <origin xyz="1.1 0 0.5" rpy="0 0 0"/>
        <axis xyz="0 0 1"/>
        <limit lower="-0.523599" upper="0.523599" effort="0" velocity="0"/>
    </joint>

    <link name="crane_link1">
        <visual>
            <origin xyz="0 0 0" rpy="1.5708 0 0" />
            <geometry>
               <cylinder length="0.4" radius="0.2"/>
            </geometry>
            <material name="gold"/>
        </visual>
        <collision>
            <origin xyz="0 0 0" rpy="1.5708 0 0" />
            <geometry>
                <cylinder length="0.4" radius="0.2"/>
            </geometry>
        </collision>  

        <visual>
            <origin xyz="-1.698 0 0" rpy="0 0 0" />
            <geometry>
               <box size="3.396 0.4 0.4"/>
            </geometry>
            <material name="gold"/>
        </visual>
        <collision>
            <origin xyz="-1.698 0 0" rpy="0 0 0" />
            <geometry>
                <box size="3.396 0.4 0.4"/>
            </geometry>
        </collision>
    </link>


    <joint name="joint0_2" type="revolute">
        <parent link="crane_yaw"/> 
        <child link="crane_link1"/>
        <origin xyz="0 0 0.3" rpy="0 1.5708 0"/>
        <axis xyz="0 1 0"/>
        <limit lower="0.0" upper="1.5708" effort="0" velocity="0"/>
    </joint>


    <link name="crane_link2">
        <visual>
            <origin xyz="1.132 0 0" rpy="0 0 0" />
            <geometry>
               <box size="2.264 0.2 0.2"/>
            </geometry>
            <material name="gold"/>
        </visual>
        <collision>
            <origin xyz="1.132 0 0" rpy="0 0 0" />
            <geometry>
                <box size="2.264 0.2 0.2"/>
            </geometry>
        </collision>
    </link>

    <joint name="joint0_3" type="prismatic">
        <parent link="crane_link1"/>
        <child link="crane_link2"/>
        <origin xyz="-3.396 0 0" rpy="0 0 0"/>
        <axis xyz="-1 0 0"/>
        <limit lower="0.0" upper="2.264" effort="0" velocity="0"/>
    </joint>
    
    <link name="tip">
        <visual>
            <!-- z = (-0.17 - 0.1) -->
            <origin xyz="-0.1 0 -0.17" rpy="0 1.5708 0" />
            <geometry>
               <box size="0.34 0.2 0.2"/>
            </geometry>
            <material name="gold"/>
        </visual>
        <collision>
            <origin xyz="-0.1 0 -0.17" rpy="0 1.5708 0" />
            <geometry>
                <box size="0.34 0.2 0.2"/>
            </geometry>
        </collision>   
    </link>

    <joint name="tip_joint" type="fixed">
        <parent link="crane_link2"/>
        <child link="tip"/>
        <origin xyz="0 0 -0.1" rpy="0 -1.26165662836 0"/>
    </joint>

</robot>

