<?xml version="1.0" ?>
<robot name="rover_crane">

    <material name="gold">
        <color rgba="1 0.882 0 1"/>
    </material>

    <link name="rover_base_link">        
        <visual>
            <origin xyz="0 0 0.125" rpy="0 0 0" />
            <geometry>
               <box size="2.6 1.5 0.2"/>
            </geometry>
            <material name="gold"/>
        </visual>
        <collision>
            <origin xyz="0 0 0.125" rpy="0 0 0" />
            <geometry>
                <box size="2.6 1.5 0.2"/>
            </geometry>
        </collision>

        <visual>
            <!-- 1.3 - 0.32 -->
            <origin xyz=".98 0 0.35" rpy="0 0 0" />
            <geometry>
               <box size="0.64 1.5 0.3"/>
            </geometry>
            <material name="gold"/>
        </visual>
        <collision>
            <origin xyz=".98 0 0.35" rpy="0 0 0" />
            <geometry>
                <box size="0.64 1.5 0.3"/>
            </geometry>
        </collision>  
    </link>
    
    <link name="crane_base_link"/>

    <joint name="fix_to_chassis" type="fixed">
        <parent link="rover_base_link"/>
        <child link="crane_base_link"/>
        <origin xyz="1.1 0 0.5" rpy="0 0 0"/>
    </joint>

    <link name="crane_yaw">
        <visual>
            <origin xyz="0 0 0.05" rpy="0 0 0" />
            <geometry>
               <cylinder length="0.1" radius="0.2"/>
            </geometry>
            <material name="gold"/>
        </visual>
        <collision>
            <origin xyz="0 0 0.05" rpy="0 0 0" />
            <geometry>
                <cylinder length="0.1" radius="0.2"/>
            </geometry>
        </collision>    
    </link>
    
    <joint name="joint0_1" type="revolute">
        <parent link="crane_base_link"/>
        <child link="crane_yaw"/>
        <origin xyz="0 0 0" rpy="0 0 0"/>
        <axis xyz="0 0 1"/>
        <limit lower="-0.523599" upper="0.523599" effort="0" velocity="0"/>
    </joint>

    <link name="crane_link1">
        <visual>
            <origin xyz="0 0 0" rpy="1.5708 0 0" />
            <geometry>
               <cylinder length="0.4" radius="0.2"/>
            </geometry>
            <material name="gold"/>
        </visual>
        <collision>
            <origin xyz="0 0 0" rpy="1.5708 0 0" />
            <geometry>
                <cylinder length="0.4" radius="0.2"/>
            </geometry>
        </collision>  

        <visual>
            <origin xyz="-0.8 0 0" rpy="0 0 0" />
            <geometry>
               <box size="1.6 0.4 0.4"/>
            </geometry>
            <material name="gold"/>
        </visual>
        <collision>
            <origin xyz="-0.8 0 0" rpy="0 0 0" />
            <geometry>
                <box size="1.6 0.4 0.4"/>
            </geometry>
        </collision>
    </link>


    <joint name="joint0_2" type="revolute">
        <parent link="crane_yaw"/> 
        <child link="crane_link1"/>
        <origin xyz="0 0 0.3" rpy="0 1.5708 0"/>
        <axis xyz="0 1 0"/>
        <limit lower="0.0" upper="1.5708" effort="0" velocity="0"/>
    </joint>


    <link name="crane_link2">
        <visual>
            <origin xyz="0.6133 0 0" rpy="0 0 0" />
            <geometry>
               <box size="1.2267 0.35 0.35"/>
            </geometry>
            <material name="gold"/>
        </visual>
        <collision>
            <origin xyz="0.6133 0 0" rpy="0 0 0" />
            <geometry>
                <box size="1.2267 0.35 0.35"/>
            </geometry>
        </collision>
    </link>

    <joint name="joint0_3" type="prismatic">
        <parent link="crane_link1"/>
        <child link="crane_link2"/>
        <origin xyz="-1.6 0 0" rpy="0 0 0"/>
        <axis xyz="-1 0 0"/>
        <limit lower="0.0" upper="1.2267" effort="0" velocity="0"/>
    </joint>

    <link name="crane_link3">
        <visual>
            <origin xyz="0.6133 0 0" rpy="0 0 0" />
            <geometry>
               <box size="1.2267 0.3 0.3"/>
            </geometry>
            <material name="gold"/>
        </visual>
        <collision>
            <origin xyz="0.6133 0 0" rpy="0 0 0" />
            <geometry>
                <box size="1.2267 0.3 0.3"/>
            </geometry>
        </collision>
    </link>

    <joint name="joint0_4" type="prismatic">
        <parent link="crane_link2"/>
        <child link="crane_link3"/>
        <origin xyz="0 0 0" rpy="0 0 0"/>
        <axis xyz="-1 0 0"/>
        <limit lower="0.0" upper="1.2267" effort="0" velocity="0"/>
    </joint>

    <link name="crane_link4">
        <visual>
            <origin xyz="0.6133 0 0" rpy="0 0 0" />
            <geometry>
               <box size="1.2267 0.25 0.25"/>
            </geometry>
            <material name="gold"/>
        </visual>
        <collision>
            <origin xyz="0.6133 0 0" rpy="0 0 0" />
            <geometry>
                <box size="1.2267 0.25 0.25"/>
            </geometry>
        </collision>
    </link>

    <joint name="joint0_5" type="prismatic">
        <parent link="crane_link3"/>
        <child link="crane_link4"/>
        <origin xyz="0 0 0" rpy="0 0 0"/>
        <axis xyz="-1 0 0"/>
        <limit lower="0.0" upper="1.2267" effort="0" velocity="0"/>
    </joint>

    <link name="tip">
        <visual>
            <!-- 0.5 + 0.054 -->
            <origin xyz="0 0 -0.554" rpy="0 0 0" />
            <geometry>
               <box size="0.2 0.2 1.0"/>
            </geometry>
            <material name="gold"/>
        </visual>
        <collision>
            <origin xyz="0 0 -0.554" rpy="0 0 0" />
            <geometry>
               <box size="0.2 0.2 1.0"/>
            </geometry>
            <material name="gold"/>
        </collision>
    </link>

    <joint name="tip_joint" type="fixed">
        <parent link="crane_link4"/>
        <child link="tip"/>
        <!-- 90 - 68.7 -->
        <origin xyz="0 0 0" rpy="0 -0.371755130675 0"/>
    </joint>

</robot>

